{"cells":[{"cell_type":"markdown","metadata":{"id":"ORNxMOj3Tprs"},"source":["# Recursividad"]},{"cell_type":"markdown","metadata":{},"source":["#### La **recursividad** ( o **recursión**) es la propiedad que posee un una  función de llamarse a sí misma. Una **función recursiva** es una función que se invoca a sí misma de forma *directa* o *indirecta*. En recursión directa el código de la función $f()$ contiene una sentencia que invoca a $f()$, mientras que en recursión indirecta $f()$ invoca a una  función $g()$ que invoca a su vez a la función $h()$, y así sucesivamente hasta que se invoca de nuevo a la función $f()$. Un requisito para que un algoritmo recursivo sea correcto es que no genere una secuencia infinita de llamadas sobre sí mismo ya que cualquier algoritmo que genere una secuencia de este tipo puede no terminar nunca.\n"]},{"cell_type":"markdown","metadata":{},"source":["#### En matemáticas existen numerosas funciones que tienen carácter recursivo de igual modo numerosas circunstancias y situaciones de la vida ordinaria tienen carácter recursivo."]},{"cell_type":"markdown","metadata":{},"source":["## Recursión versus iteración"]},{"cell_type":"markdown","metadata":{},"source":["#### Tanto la iteración como la recursión se basan en una ***estructura de control***: La iteración utiliza una ***estructura repetitiva***,  mientras que la recursión  utiliza una ***estructura de selección***. \n","\n","#### La iteración y la recursión implican ambas ***repetición***: la iteración utiliza explícitamente una estructura repetitiva, mientras que la iteración consigue la repetición mediante llamadas repetidas a funciones. \n","\n","#### La recursión invoca repetidamente al mecanismo de llamadas a funciones y en consecuencia se necesita un tiempo suplementario para  realizar cada llamada. Esta característica puede resultar cara en tiempo de procesador y espacio de memoria. La iteración se produce dentro de una función de modo que las operaciones suplementarias de las llamadas a la función y asignación de memoria adicional son omitidas. \n","\n","#### Se puede utilizar la recursividad como una alternativa a la iteración. La recursión es una herramienta poderosa e importante en la resolución de problemas y en programación. Una solución recursiva es normalmente menos eficiente en términos de tiempo de computadora que una solución iterativa debido a las operaciones auxiliares que llevan consigo las llamadas suplementarias a las funciones; sin embargo, en muchas circunstancias el uso de la recursión permite a los programadores especificar soluciones naturales, sencillas, que serían, en caso contrario, difíciles de resolver. La razón fundamental para elegir la recursión es que existen numerosos problemas complejos que poseen naturaleza recursiva y, en consecuencia, son más fáciles de diseñar e implementar con algoritmos de este tipo."]},{"cell_type":"markdown","metadata":{},"source":["## Ejemplo\n","\n","#### Escribe una función recursiva en Python que reciba como argumento un número entero positivo $n$ y determine  el factorial de $n$.\n","#### **Solución:**"]},{"cell_type":"code","execution_count":1,"metadata":{},"outputs":[{"name":"stdout","output_type":"stream","text":["El factorial de 5 es 120 \n"]}],"source":["def factorial(n):\n","    if n == 0:\n","        return 1\n","    else:\n","        return n * factorial(n-1)\n","\n","n = int(input('Ingresa un número entero positivo'))\n","print(f\"El factorial de {n} es: {factorial(n)} \")"]},{"cell_type":"markdown","metadata":{},"source":["## Ejemplo\n","\n","#### Escribe una función recursiva en Python que reciba como argumento un número entero positivo $n$ y determine  la suma de los primeros $n$ números enteros positivos.\n","\n","#### **Solución:**"]},{"cell_type":"code","execution_count":2,"metadata":{},"outputs":[{"name":"stdout","output_type":"stream","text":["La suma de los primeros 100 números enteros positivos es: 5050 \n"]}],"source":["def suma_gauss(n):\n","    if n == 1:\n","        return 1\n","    else:\n","        return n + suma_gauss(n-1)\n","\n","n = int(input('Ingresa un número entero positivo'))\n","print(f\"La suma de los primeros {n} números enteros positivos es: {suma_gauss(n)} \")"]},{"cell_type":"code","execution_count":null,"metadata":{},"outputs":[],"source":[]},{"cell_type":"markdown","metadata":{},"source":["## Ejemplo\n","\n","#### Escribe una función recursiva en Python que reciba como argumento un número entero positivo $n$ y determine $n$-ésimo término de la sucesión de Fibonacci.\n","\n","#### **Solución**"]},{"cell_type":"code","execution_count":22,"metadata":{},"outputs":[{"name":"stdout","output_type":"stream","text":["El 2-ésimo término de la sucesión de Fibonacci es: 1 \n"]}],"source":["def nfibo(n):\n","    if n == 1 or n == 2:\n","        return 1\n","    else:\n","        return nfibo(n-1) + nfibo(n-2)\n","\n","n = int(input('Ingresa un número entero positivo'))\n","\n","print(f\"El {n}-ésimo término de la sucesión de Fibonacci es: {nfibo(n)} \")"]},{"cell_type":"markdown","metadata":{},"source":["## Ejemplo\n","\n","#### Escribe una función recursiva en Python que reciba como argumento un número entero positivo $n$ y determine su correespondiente expresión en binario.\n","\n","### Solución:"]},{"cell_type":"code","execution_count":12,"metadata":{},"outputs":[{"name":"stdout","output_type":"stream","text":["10\n"]}],"source":["def dec_bin(n):\n","    if n//2 == 0:\n","        return str(n%2)\n","    else:\n","        return dec_bin(n//2) + str(n%2)\n","    \n","print(dec_bin(2))"]},{"cell_type":"markdown","metadata":{},"source":["## Ejemplo\n","\n","#### Escribe una función recursiva en Python que reciba como argumento dos números enteros positivos $a$ y $b$  y determine el producto $a \\times b$ \n","\n","### Solución:"]},{"cell_type":"code","execution_count":21,"metadata":{},"outputs":[{"name":"stdout","output_type":"stream","text":["0\n"]}],"source":["def producto_sumando(a,b):\n","    if  a == 0:\n","        return 0\n","    else:\n","        return b + producto_sumando(a-1,b) \n","    \n","print(producto_sumando(2,0))"]},{"cell_type":"markdown","metadata":{},"source":["# Errores y excepciones\n"]},{"cell_type":"markdown","metadata":{},"source":["#### En un programa podemos encontrarnos con distintos tipos de errores pero a grandes rasgos podemos decir que todos los errores pertenecen a una de las siguientes categorías."]},{"cell_type":"markdown","metadata":{},"source":["\n","#### ***Errores de sintaxis:*** estos errores son seguramente los más simples de resolver, pues son detectados por el intérprete (o por el compilador, según el tipo de lenguaje que estemos utilizando) al procesar el código fuente y generalmente son consecuencia de equivocaciones al escribir el programa. En el caso de Python estos errores son indicados con un mensaje `SyntaxError`. Por ejemplo, si trabajando con Python intentamos definir una función y en lugar de `def` escribimos `dev`.\n","\n","#### ***Errores semánticos:*** se dan cuando un programa, a pesar de no generar mensajes de error, no produce el resultado esperado. Esto puede deberse, por ejemplo, a un algoritmo incorrecto o a la omisión de una sentencia.\n","\n","#### ***Errores de ejecución:*** estos errores aparecen durante la ejecución del programa y su origen puede ser diverso. En ocasiones pueden producirse por un uso incorrecto del programa por parte del usuario, por ejemplo si el usuario ingresa una cadena cuando se espera un número. En otras ocasiones pueden deberse a errores de programación, por ejemplo si una función intenta acceder a la quinta posición de una lista de 3 elementos o realizar una división por cero. Una causa común de errores de ejecución que generalmente excede al programador y al usuario, son los recursos externos al programa, por ejemplo si el programa intenta leer un archivo y el mismo se encuentra dañado.\n"]},{"cell_type":"markdown","metadata":{},"source":["#### Tanto a los errores de sintaxis como a los semánticos se los puede detectar y corregir durante la construcción del programa ayudados por el intérprete y la ejecución de pruebas. Pero no ocurre esto con los errores de ejecución ya que no siempre es posible saber cuando ocurrirán y puede resultar muy complejo (o incluso casi imposible) reproducirlos. Es por ello nos centraremos en cómo preparar nuestros programas para lidiar con este tipo de errores."]},{"cell_type":"markdown","metadata":{},"source":["#### Los errores de ejecución son llamados comúnmente **excepciones**. Durante la ejecución de un programa, si dentro de una función surge una excepción y la función no la *maneja*, la excepción se propaga hacia la función que la invocó, si esta otra tampoco la *maneja*, la excepción continua propagándose hasta llegar a la función inicial del programa y si esta tampoco la *maneja* se interrumpe la ejecución del programa."]},{"cell_type":"markdown","metadata":{},"source":["## Excepciones en Python"]},{"cell_type":"markdown","metadata":{},"source":["\n","#### Las ***excepciones*** en Python son una herramienta muy potente, se trata de una forma de controlar el comportamiento de un programa cuando se produce un error.\n","\n","#### Esto es muy importante ya que salvo que tratemos este error, el programa se parará, y esto es algo que en determinadas aplicaciones no es una opción válida."]},{"cell_type":"markdown","metadata":{},"source":["#### Imaginemos que tenemos el siguiente código con dos variables `a` y `b` y realizamos su división `a/b`."]},{"cell_type":"code","execution_count":null,"metadata":{},"outputs":[],"source":["a = 4\n","b = 2\n","c = a/b\n"]},{"cell_type":"markdown","metadata":{},"source":["#### Pero imaginemos ahora que por cualquier motivo las variables tienen otro valor, y que por ejemplo `b` tiene el valor `0`. **Si intentamos hacer la división entre cero**, este programa dará un error y su ejecución terminará de manera abrupta."]},{"cell_type":"code","execution_count":null,"metadata":{},"outputs":[],"source":["a = 4\n","b = 0\n","print(a/b)"]},{"cell_type":"markdown","metadata":{},"source":["#### Ese *error* que decimos que ha ocurrido es lanzado por Python ya que la división entre cero es una operación que matemáticamente no está definida. Se trata de la excepción` ZeroDivisionError`. "]},{"cell_type":"markdown","metadata":{},"source":["#### **Veamos un ejemplo con otra excepción**. ¿Que pasaría si intentásemos sumar un número con un texto? Evidentemente esto no tiene ningún sentido, y Python define una excepción para esto llamada `TypeError`."]},{"cell_type":"code","execution_count":null,"metadata":{},"outputs":[],"source":["print(2 + \"2\")"]},{"cell_type":"code","execution_count":null,"metadata":{},"outputs":[],"source":["x=int(input('Ingresa un numero'))"]},{"cell_type":"markdown","metadata":{},"source":["#### Es muy importante controlar las excepciones, porque por muchas comprobaciones que realicemos es posible que en algún momento ocurra una, y si no se hace nada el programa se detendrá."]},{"cell_type":"markdown","metadata":{},"source":["#### **¿Puedes imaginar que en un avión, el metro de la CDMX o un cajero automático ocurra un error y se detenga por completo?**"]},{"cell_type":"markdown","metadata":{},"source":[" ## Manejo de excepciones"]},{"cell_type":"markdown","metadata":{},"source":["#### Una primera aproximación al control de excepciones podría ser el siguiente ejemplo. Podemos realizar una comprobación manual de que no estamos dividiendo por cero, para así evitar tener un error tipo `ZeroDivisionError`."]},{"cell_type":"code","execution_count":null,"metadata":{},"outputs":[],"source":["a = 5\n","b = 0\n","if b!=0:\n","    print(a/b)\n","else:\n","    print(\"No se puede dividir!\")"]},{"cell_type":"markdown","metadata":{},"source":["#### Para el **manejo de excepciones** Python provee ciertas palabras reservadas, que nos permiten manejar las excepciones que puedan surgir y tomar acciones de recuperación para evitar la interrupción del programa o, al menos, para realizar algunas acciones adicionales antes de interrumpir el programa."]},{"cell_type":"markdown","metadata":{},"source":["#### En el caso de Python, el manejo de excepciones se hace mediante los bloques que utilizan las sentencias `try`, `except` y `finally`"]},{"cell_type":"markdown","metadata":{},"source":["# Sentencias `try` - `except`"]},{"cell_type":"markdown","metadata":{},"source":["#### Las excepciones que hemos visto antes, pueden ser capturadas y manejadas adecuadamente, sin que el programa se detenga. Veamos un ejemplo con la división entre cero."]},{"cell_type":"code","execution_count":null,"metadata":{},"outputs":[],"source":["a = 5; b = 0\n","try:\n","    c = a/b\n","    print(c)\n","except:\n","    print(\"¡No se ha podido realizar la división, division entre cero!\")"]},{"cell_type":"markdown","metadata":{},"source":["#### En este caso, se levantó la excepción `ZeroDivisionError` cuando se quiso hacer la división. Para evitar que se levante la excepción y se detenga la ejecución del programa, se utiliza el bloque `try-except`."]},{"cell_type":"markdown","metadata":{},"source":["#### En este caso no verificamos que `b!=0`. Directamente intentamos realizar la división y en el caso de que se lance la excepción `ZeroDivisionError`, la ***capturamos*** y la ***tratamos*** adecuadamente."]},{"cell_type":"markdown","metadata":{},"source":["* ####  La sentencia `try` **contiene el bloque de código que puede *ocasionar* o *levantar* una excepción** o un error. Se utiliza el término levantar para referirse a la acción de generar una excepción.\n","\n","* ####  A continuación se ubica el bloque `except`, que se encarga de capturar la excepción y nos da la oportunidad de procesarla mostrando por ejemplo un mensaje adecuado al usuario. **Contiene el bloque de código que se ejecutará si y sólo si un error es detectado** en nuestro código. "]},{"cell_type":"markdown","metadata":{},"source":["#### Por ejemplo, las siguientes líneas de código siguiente nos dará error si el usuario introduce letras en lugar de números:  "]},{"cell_type":"code","execution_count":null,"metadata":{},"outputs":[],"source":["num=int(input('¿Cuantos años tienes?'))\n","print(f'Tienes  {num} años')"]},{"cell_type":"markdown","metadata":{},"source":["#### Por lo tanto podemos implementar la sentencia `try-except`:"]},{"cell_type":"code","execution_count":null,"metadata":{},"outputs":[],"source":["try:\n","    num=int(input('¿Cuantos años tienes?'))\n","    print(f'Tienes  {num} años')\n","except:\n","    print('Tipo de dato incorrecto')\n","    num=int(input('¿Cuantos años tienes?'))\n","    print(f'Tienes  {num} años')"]},{"cell_type":"markdown","metadata":{},"source":["## Multiples excepciones"]},{"cell_type":"markdown","metadata":{},"source":["#### Dado que dentro de un mismo bloque `try` pueden producirse excepciones de distinto tipo, es posible utilizar varios bloques `except`, cada uno para capturar un tipo distinto de excepción."]},{"cell_type":"markdown","metadata":{},"source":["#### En algunas ocasiones dentro de un mismo bloque `try` pueden producirse excepciones de distinto tipo y será necesario agregar **multiples excepciones**, para esto es posible utilizar varios bloques `except`, cada uno para capturar un tipo *distinto de excepción*. \n","\n","#### Esto se hace especificando a continuación de la sentencia `except` el nombre de la excepción (Python cuenta con palabras reservadas para *clasificar el tipo de error*) que se pretende capturar. Un mismo bloque `except` puede atrapar varios tipos de excepciones, lo cual se hace especificando los nombres de la excepciones separados por comas y entre parentesis a continuación de la palabra `except`. Es importante destacar que si bien luego de un bloque `try` puede haber varios bloques `except`, se ejecutará, a lo más uno de ellos."]},{"cell_type":"code","execution_count":null,"metadata":{},"outputs":[],"source":["try:\n","    c = 5/0      \n","    #d = 2 + \"Hola\"\n","except ZeroDivisionError:\n","    print(\"No se puede dividir entre cero!\")\n","except TypeError:\n","    print(\"Problema de tipos!\")"]},{"cell_type":"markdown","metadata":{},"source":["#### Puedes también hacer que un determinado número de excepciones se traten de la misma manera con el mismo bloque de código. Sin embargo suele ser más interesante tratar a diferentes excepciones de diference manera."]},{"cell_type":"code","execution_count":null,"metadata":{},"outputs":[],"source":["try:\n","    #c = 5/0       \n","    d = 2 + \"Hola\" \n","except (ZeroDivisionError, TypeError):\n","    print(\"Excepcion ZeroDivisionError o TypeError\")"]},{"cell_type":"markdown","metadata":{},"source":["#### Si no sabes que excepción puede saltar, puedes usar la clase genérica `Exception`. En este caso se controla cualquier tipo de excepción. De hecho todas las excepciones heredan de `Exception`."]},{"cell_type":"code","execution_count":null,"metadata":{},"outputs":[],"source":["try:\n","    #c = 5/0       \n","    d = 2 + \"Hola\" \n","except Exception:\n","    print(\"Ha ocurrido una excepción\")"]},{"cell_type":"markdown","metadata":{},"source":["#### No obstante hay una forma de saber que excepción ha sido la que ha ocurrido."]},{"cell_type":"code","execution_count":null,"metadata":{},"outputs":[],"source":["try:\n","    d = 2 + \"Hola\" \n","except Exception as ex:\n","    print(\"Ha habido una excepción\", type(ex))\n"]}],"metadata":{"colab":{"provenance":[]},"kernelspec":{"display_name":"Python 3","language":"python","name":"python3"},"language_info":{"codemirror_mode":{"name":"ipython","version":3},"file_extension":".py","mimetype":"text/x-python","name":"python","nbconvert_exporter":"python","pygments_lexer":"ipython3","version":"3.11.1"},"orig_nbformat":4,"vscode":{"interpreter":{"hash":"1606ed296fe21ab67c1d4b49f3f22d72247524c93f58d404930dbd4d15d6017c"}}},"nbformat":4,"nbformat_minor":0}
